Workbook
Name EntityList: 'Lookups & Data Validation'!$A$2:$A$5
Name TransactionTypeList: 'Lookups & Data Validation'!$B$2:$B$9
Name StatusList: 'Lookups & Data Validation'!$C$2:$C$5
Name ValuationMethodList: 'Lookups & Data Validation'!$D$2:$D$8
Name MarkTypeList: 'Lookups & Data Validation'!$E$2:$E$7
Name SectorList: 'Lookups & Data Validation'!$F$2:$F$9
Name AssetTypeList: 'Lookups & Data Validation'!$G$2:$G$6
Name YesNoList: 'Lookups & Data Validation'!$H$2:$H$3
Name LeadCoList: 'Lookups & Data Validation'!$I$2:$I$3

Sheet Cover & Instructions
A1: Private Investment & Portfolio Valuation Workbook
A2: Purpose
A3: • Use the yellow cells in the data tabs for manual updates. Formula and output cells are protected visually and should update automatically when the workbook recalculates.
A4: • Track all actual capital calls and distributions in the Capital Call & Distribution Ledger. XIRR calculations are based on those dated cash flows plus the selected ending valuation view.
A5: • Maintain conservative marks in the Official Valuation Ledger, internal operating marks in the Internal Valuation Model, and upside case values in Exit Scenario Valuation.
A6: • Use the Entity Summary Dashboard for entity-level review and the Combined Portfolio Dashboard for overall portfolio reporting.
A7: • Refresh formulas in Excel after opening if calculation mode is manual. Filters, tables, and named ranges are already set up for ongoing use.
A10: Entities covered | D10: Workbook use
A11: Beaman Ventures | D11: 1. Update Investment Master for new positions and ownership.
A12: Lee Beaman | D12: 2. Add actual capital calls and distributions in Cash Flow Ledger.
A13: Kat Trust | D13: 3. Maintain official, internal, and exit marks on their respective tabs.
A14: Nat Trust | D14: 4. Review dashboards and audit checks before distribution.
A16: Workbook architecture
A17: Tab | B17: Purpose
A18: Entity Summary Dashboard | B18: Entity-level snapshot across Beaman Ventures, Lee Beaman, Kat Trust, and Nat Trust.
A19: Combined Portfolio Dashboard | B19: Whole-portfolio KPI view and chart package for internal review.
A20: Investment Master | B20: One-row-per-investment reference table with ownership and valuation rollups.
A21: Cash Flow Ledger | B21: Source-of-truth dated capital calls, distributions, dividends, and exit cash flows.
A22: Official Valuation Ledger | B22: Conservative reporting marks anchored to external valuation events.
A23: Internal Valuation Model | B23: Team underwriting view using EBITDA, revenue, NAV, or manual override.
A24: Exit Scenario Valuation | B24: Upside/downside planning case based on realistic exit assumptions.
A25: Audit Checks | B25: Control framework to validate that source data and rollups tie.

Sheet Assumptions & Methodology
A1: Assumptions & Methodology
A2: Purpose
A3: • Official valuation represents the conservative reporting view and should stay at cost until there is a real external marker event.
A4: • Internal valuation reflects the investment team's best estimate using selected valuation methods such as EBITDA, revenue, NAV, or manual override.
A5: • Exit scenario value is a planning case and should not be used as official NAV.
A6: • Official / Internal / Exit XIRR all use actual dated cash flows from the ledger, plus the relevant ending value as a terminal positive cash flow dated as of today.
A7: • TVPI = (Distributions + Residual Value) / Paid-In Capital. DPI = Distributions / Paid-In Capital. RVPI = Residual Value / Paid-In Capital. MOIC is shown as turns.
A8: • Entity-level NAV is allocated using current ownership percentages maintained in the Investment Master tab.
A10: Valuation views
A11: Official Conservative Mark | B11: Board and reporting view. Stay at cost until a priced round, market transaction, or credible external marker supports a change.
A12: Internal Valuation Mark | B12: Best internal view of equity value using the selected operating valuation framework and team judgment.
A13: Potential Exit Value | B13: Scenario planning view only. Useful for upside framing, capital allocation decisions, and embedded value discussion.

Sheet Entity Summary Dashboard
A1: Entity Summary Dashboard
A3: Total Invested Capital | B3: =SUM(tblEntityPerf[Total invested capital]) | D3: By entity snapshot
A4: Total Distributions | B4: =SUM(tblEntityPerf[Total distributions]) | D4: Entity | E4: Invested | F4: Distributed | G4: Official NAV | H4: Internal NAV | I4: Exit NAV | J4: TVPI | K4: Official XIRR
A5: Official NAV | B5: =SUM(tblEntityPerf[Official NAV]) | D5: ='Entity-Level Performance'!A4 | E5: ='Entity-Level Performance'!B4 | F5: ='Entity-Level Performance'!C4 | G5: ='Entity-Level Performance'!E4 | H5: ='Entity-Level Performance'!F4 | I5: ='Entity-Level Performance'!G4 | J5: ='Entity-Level Performance'!H4 | K5: ='Entity-Level Performance'!K4
A6: Internal NAV | B6: =SUM(tblEntityPerf[Internal NAV]) | D6: ='Entity-Level Performance'!A5 | E6: ='Entity-Level Performance'!B5 | F6: ='Entity-Level Performance'!C5 | G6: ='Entity-Level Performance'!E5 | H6: ='Entity-Level Performance'!F5 | I6: ='Entity-Level Performance'!G5 | J6: ='Entity-Level Performance'!H5 | K6: ='Entity-Level Performance'!K5
A7: Exit Scenario Value | B7: =SUM(tblEntityPerf[Exit Scenario NAV]) | D7: ='Entity-Level Performance'!A6 | E7: ='Entity-Level Performance'!B6 | F7: ='Entity-Level Performance'!C6 | G7: ='Entity-Level Performance'!E6 | H7: ='Entity-Level Performance'!F6 | I7: ='Entity-Level Performance'!G6 | J7: ='Entity-Level Performance'!H6 | K7: ='Entity-Level Performance'!K6
A8: Official XIRR | B8: =IFERROR(LET(cf,tblCashFlows[Net Cash Flow],dt,tblCashFlows[Transaction Date],tv,SUM(tblEntityPerf[Official NAV]),XIRR(VSTACK(cf,tv),VSTACK(dt,TODAY()))),"") | D8: ='Entity-Level Performance'!A7 | E8: ='Entity-Level Performance'!B7 | F8: ='Entity-Level Performance'!C7 | G8: ='Entity-Level Performance'!E7 | H8: ='Entity-Level Performance'!F7 | I8: ='Entity-Level Performance'!G7 | J8: ='Entity-Level Performance'!H7 | K8: ='Entity-Level Performance'!K7

Sheet Combined Portfolio Dashboard
A1: Combined Portfolio Dashboard
A3: Total Invested Capital | B3: =SUM(tblInvestments[Total invested capital]) | D3: Internal XIRR | E3: =IFERROR(LET(cf,tblCashFlows[Net Cash Flow],dt,tblCashFlows[Transaction Date],tv,SUM(tblInvestments[Internal current value]),XIRR(VSTACK(cf,tv),VSTACK(dt,TODAY()))),"") | F3: Top investments by value
A4: Total Distributions | B4: =SUM(tblInvestments[Total distributions]) | D4: Exit XIRR | E4: =IFERROR(LET(cf,tblCashFlows[Net Cash Flow],dt,tblCashFlows[Transaction Date],tv,SUM(tblInvestments[Exit scenario value]),XIRR(VSTACK(cf,tv),VSTACK(dt,TODAY()))),"") | F4: Investment | G4: Official Value | H4: Internal Value | I4: Exit Value | J4: Gain / Loss
A5: Official NAV | B5: =SUM(tblInvestments[Official current value]) | D5: Realized Value | E5: =SUM(tblInvestments[Total distributions]) | F5: ='Investment-Level Performance'!B4 | G5: ='Investment-Level Performance'!F4 | H5: ='Investment-Level Performance'!G4 | I5: ='Investment-Level Performance'!H4 | J5: ='Investment-Level Performance'!Q4
A6: Internal NAV | B6: =SUM(tblInvestments[Internal current value]) | D6: Unrealized Value | E6: =SUM(tblInvestments[Official current value]) | F6: ='Investment-Level Performance'!B5 | G6: ='Investment-Level Performance'!F5 | H6: ='Investment-Level Performance'!G5 | I6: ='Investment-Level Performance'!H5 | J6: ='Investment-Level Performance'!Q5
A7: Exit Scenario Value | B7: =SUM(tblInvestments[Exit scenario value]) | D7: Embedded Value Creation | E7: =SUM(tblInvestments[Internal current value])-SUM(tblInvestments[Official current value]) | F7: ='Investment-Level Performance'!B6 | G7: ='Investment-Level Performance'!F6 | H7: ='Investment-Level Performance'!G6 | I7: ='Investment-Level Performance'!H6 | J7: ='Investment-Level Performance'!Q6
A8: Official TVPI | B8: =IFERROR((SUM(tblInvestments[Total distributions])+SUM(tblInvestments[Official current value]))/SUM(tblInvestments[Total invested capital]),"") | D8: Exit Upside | E8: =SUM(tblInvestments[Exit scenario value])-SUM(tblInvestments[Internal current value]) | F8: ='Investment-Level Performance'!B7 | G8: ='Investment-Level Performance'!F7 | H8: ='Investment-Level Performance'!G7 | I8: ='Investment-Level Performance'!H7 | J8: ='Investment-Level Performance'!Q7
A9: Internal TVPI | B9: =IFERROR((SUM(tblInvestments[Total distributions])+SUM(tblInvestments[Internal current value]))/SUM(tblInvestments[Total invested capital]),"") | D9: Number of Investments | E9: =ROWS(tblInvestments[Investment ID]) | F9: ='Investment-Level Performance'!B8 | G9: ='Investment-Level Performance'!F8 | H9: ='Investment-Level Performance'!G8 | I9: ='Investment-Level Performance'!H8 | J9: ='Investment-Level Performance'!Q8
A10: Exit TVPI | B10: =IFERROR((SUM(tblInvestments[Total distributions])+SUM(tblInvestments[Exit scenario value]))/SUM(tblInvestments[Total invested capital]),"") | D10: Number of Active Investments | E10: =COUNTIF(tblInvestments[Status],"Active")+COUNTIF(tblInvestments[Status],"Partially Realized") | F10: ='Investment-Level Performance'!B9 | G10: ='Investment-Level Performance'!F9 | H10: ='Investment-Level Performance'!G9 | I10: ='Investment-Level Performance'!H9 | J10: ='Investment-Level Performance'!Q9
A11: Official XIRR | B11: =IFERROR(LET(cf,tblCashFlows[Net Cash Flow],dt,tblCashFlows[Transaction Date],tv,SUM(tblInvestments[Official current value]),XIRR(VSTACK(cf,tv),VSTACK(dt,TODAY()))),"") | D11: Number of Realized Investments | E11: =COUNTIF(tblInvestments[Status],"Realized") | F11: ='Investment-Level Performance'!B10 | G11: ='Investment-Level Performance'!F10 | H11: ='Investment-Level Performance'!G10 | I11: ='Investment-Level Performance'!H10 | J11: ='Investment-Level Performance'!Q10
F12: ='Investment-Level Performance'!B11 | G12: ='Investment-Level Performance'!F11 | H12: ='Investment-Level Performance'!G11 | I12: ='Investment-Level Performance'!H11 | J12: ='Investment-Level Performance'!Q11

Sheet Investment Master
A1: Investment Master | One row per investment
A2: Yellow cells are core inputs. Formula columns roll up cash flows, current marks, and performance.
A3: Investment ID | B3: Investment Name | C3: Sector / Strategy | D3: Asset Type | E3: Status | F3: Initial Investment Date | G3: Sponsor / Manager | H3: Geography | I3: Official Valuation Method | J3: Internal Valuation Method | K3: Exit Valuation Method | L3: Board Seat? | M3: Lead / Co-invest? | N3: Commitment Amount | O3: Beaman Ventures % | P3: Lee Beaman % | Q3: Kat Trust % | R3: Nat Trust % | S3: Ownership % total | T3: Entity ownership notes | U3: Notes | V3: Total invested capital | W3: Total distributions | X3: Official current value | Y3: Internal current value | Z3: Exit scenario value | AA3: Official MOIC | AB3: Internal MOIC | AC3: Exit MOIC | AD3: Official XIRR | AE3: Internal XIRR | AF3: Exit XIRR
A4: INV-001 | B4: Atlas Data Platforms | C4: Application Software | D4: Venture Equity | E4: Active | F4: 44635 | G4: North Peak Ventures | H4: United States | I4: Priced Round | J4: Revenue multiple | K4: Revenue multiple | L4: Y | M4: Lead | N4: 3000000 | O4: 0.4 | P4: 0.3 | Q4: 0.2 | R4: 0.1 | S4: 0.08 | T4: Cross-entity core software position. | U4: Workflow automation platform serving mid-market industrial customers. | V4: =SUMIFS(tblCashFlows[Contribution Amount],tblCashFlows[Investment ID],A4) | W4: =SUMIFS(tblCashFlows[Distribution Amount],tblCashFlows[Investment ID],A4) | X4: =XLOOKUP(A4,tblOfficialMarks[Investment ID],tblOfficialMarks[New Official Value],0,0,-1) | Y4: =XLOOKUP(A4,tblInternalModel[Investment ID],tblInternalModel[Final Internal Value],0,0,-1) | Z4: =XLOOKUP(A4,tblExitScenarios[Investment ID],tblExitScenarios[Net Exit Value],0,0,-1) | AA4: =IFERROR((W4+X4)/V4,"") | AB4: =IFERROR((W4+Y4)/V4,"") | AC4: =IFERROR((W4+Z4)/V4,"") | AD4: =IFERROR(LET(cf,FILTER(tblCashFlows[Net Cash Flow],tblCashFlows[Investment ID]=A4),dt,FILTER(tblCashFlows[Transaction Date],tblCashFlows[Investment ID]=A4),XIRR(VSTACK(cf,N(X4)),VSTACK(dt,TODAY()))),"") | AE4: =IFERROR(LET(cf,FILTER(tblCashFlows[Net Cash Flow],tblCashFlows[Investment ID]=A4),dt,FILTER(tblCashFlows[Transaction Date],tblCashFlows[Investment ID]=A4),XIRR(VSTACK(cf,N(Y4)),VSTACK(dt,TODAY()))),"") | AF4: =IFERROR(LET(cf,FILTER(tblCashFlows[Net Cash Flow],tblCashFlows[Investment ID]=A4),dt,FILTER(tblCashFlows[Transaction Date],tblCashFlows[Investment ID]=A4),XIRR(VSTACK(cf,N(Z4)),VSTACK(dt,TODAY()))),"")
A5: INV-002 | B5: Harbor Health Partners | C5: Healthcare Services | D5: Growth Equity | E5: Active | F5: 44449 | G5: Oak Hill Growth | H5: United States | I5: Cost | J5: EBITDA multiple | K5: EBITDA multiple | L5: N | M5: Co-invest | N5: 2500000 | O5: 0.5 | P5: 0 | Q5: 0.25 | R5: 0.25 | S5: 0.12 | T5: Weighted toward Beaman Ventures with trust participation. | U5: Provider network services platform with recurring contracted revenue. | V5: =SUMIFS(tblCashFlows[Contribution Amount],tblCashFlows[Investment ID],A5) | W5: =SUMIFS(tblCashFlows[Distribution Amount],tblCashFlows[Investment ID],A5) | X5: =XLOOKUP(A5,tblOfficialMarks[Investment ID],tblOfficialMarks[New Official Value],0,0,-1) | Y5: =XLOOKUP(A5,tblInternalModel[Investment ID],tblInternalModel[Final Internal Value],0,0,-1) | Z5: =XLOOKUP(A5,tblExitScenarios[Investment ID],tblExitScenarios[Net Exit Value],0,0,-1) | AA5: =IFERROR((W5+X5)/V5,"") | AB5: =IFERROR((W5+Y5)/V5,"") | AC5: =IFERROR((W5+Z5)/V5,"") | AD5: =IFERROR(LET(cf,FILTER(tblCashFlows[Net Cash Flow],tblCashFlows[Investment ID]=A5),dt,FILTER(tblCashFlows[Transaction Date],tblCashFlows[Investment ID]=A5),XIRR(VSTACK(cf,N(X5)),VSTACK(dt,TODAY()))),"") | AE5: =IFERROR(LET(cf,FILTER(tblCashFlows[Net Cash Flow],tblCashFlows[Investment ID]=A5),dt,FILTER(tblCashFlows[Transaction Date],tblCashFlows[Investment ID]=A5),XIRR(VSTACK(cf,N(Y5)),VSTACK(dt,TODAY()))),"") | AF5: =IFERROR(LET(cf,FILTER(tblCashFlows[Net Cash Flow],tblCashFlows[Investment ID]=A5),dt,FILTER(tblCashFlows[Transaction Date],tblCashFlows[Investment ID]=A5),XIRR(VSTACK(cf,N(Z5)),VSTACK(dt,TODAY()))),"")
A6: INV-003 | B6: Summit Robotics | C6: Industrial Technology | D6: Venture Equity | E6: Partially Realized | F6: 43956 | G6: Forge Capital | H6: United States | I6: Priced Round | J6: Revenue multiple | K6: EBITDA multiple | L6: Y | M6: Co-invest | N6: 1200000 | O6: 0 | P6: 0.6 | Q6: 0 | R6: 0.4 | S6: 0.065 | T6: Lee / Nat co-invest with partial liquidity already received. | U6: Warehouse automation company with partial secondary liquidity realized. | V6: =SUMIFS(tblCashFlows[Contribution Amount],tblCashFlows[Investment ID],A6) | W6: =SUMIFS(tblCashFlows[Distribution Amount],tblCashFlows[Investment ID],A6) | X6: =XLOOKUP(A6,tblOfficialMarks[Investment ID],tblOfficialMarks[New Official Value],0,0,-1) | Y6: =XLOOKUP(A6,tblInternalModel[Investment ID],tblInternalModel[Final Internal Value],0,0,-1) | Z6: =XLOOKUP(A6,tblExitScenarios[Investment ID],tblExitScenarios[Net Exit Value],0,0,-1) | AA6: =IFERROR((W6+X6)/V6,"") | AB6: =IFERROR((W6+Y6)/V6,"") | AC6: =IFERROR((W6+Z6)/V6,"") | AD6: =IFERROR(LET(cf,FILTER(tblCashFlows[Net Cash Flow],tblCashFlows[Investment ID]=A6),dt,FILTER(tblCashFlows[Transaction Date],tblCashFlows[Investment ID]=A6),XIRR(VSTACK(cf,N(X6)),VSTACK(dt,TODAY()))),"") | AE6: =IFERROR(LET(cf,FILTER(tblCashFlows[Net Cash Flow],tblCashFlows[Investment ID]=A6),dt,FILTER(tblCashFlows[Transaction Date],tblCashFlows[Investment ID]=A6),XIRR(VSTACK(cf,N(Y6)),VSTACK(dt,TODAY()))),"") | AF6: =IFERROR(LET(cf,FILTER(tblCashFlows[Net Cash Flow],tblCashFlows[Investment ID]=A6),dt,FILTER(tblCashFlows[Transaction Date],tblCashFlows[Investment ID]=A6),XIRR(VSTACK(cf,N(Z6)),VSTACK(dt,TODAY()))),"")
A7: INV-004 | B7: Cedar Credit Fund II | C7: Private Credit | D7: Fund | E7: Active | F7: 44581 | G7: Cedar Capital | H7: North America | I7: Cost | J7: NAV / asset-based | K7: NAV / asset-based | L7: N | M7: Co-invest | N7: 2000000 | O7: 0.25 | P7: 0.25 | Q7: 0.25 | R7: 0.25 | S7: 0.04 | T7: Evenly funded across all four entities. | U7: Senior secured direct lending fund with quarterly distributions. | V7: =SUMIFS(tblCashFlows[Contribution Amount],tblCashFlows[Investment ID],A7) | W7: =SUMIFS(tblCashFlows[Distribution Amount],tblCashFlows[Investment ID],A7) | X7: =XLOOKUP(A7,tblOfficialMarks[Investment ID],tblOfficialMarks[New Official Value],0,0,-1) | Y7: =XLOOKUP(A7,tblInternalModel[Investment ID],tblInternalModel[Final Internal Value],0,0,-1) | Z7: =XLOOKUP(A7,tblExitScenarios[Investment ID],tblExitScenarios[Net Exit Value],0,0,-1) | AA7: =IFERROR((W7+X7)/V7,"") | AB7: =IFERROR((W7+Y7)/V7,"") | AC7: =IFERROR((W7+Z7)/V7,"") | AD7: =IFERROR(LET(cf,FILTER(tblCashFlows[Net Cash Flow],tblCashFlows[Investment ID]=A7),dt,FILTER(tblCashFlows[Transaction Date],tblCashFlows[Investment ID]=A7),XIRR(VSTACK(cf,N(X7)),VSTACK(dt,TODAY()))),"") | AE7: =IFERROR(LET(cf,FILTER(tblCashFlows[Net Cash Flow],tblCashFlows[Investment ID]=A7),dt,FILTER(tblCashFlows[Transaction Date],tblCashFlows[Investment ID]=A7),XIRR(VSTACK(cf,N(Y7)),VSTACK(dt,TODAY()))),"") | AF7: =IFERROR(LET(cf,FILTER(tblCashFlows[Net Cash Flow],tblCashFlows[Investment ID]=A7),dt,FILTER(tblCashFlows[Transaction Date],tblCashFlows[Investment ID]=A7),XIRR(VSTACK(cf,N(Z7)),VSTACK(dt,TODAY()))),"")
A8: INV-005 | B8: Meridian Consumer Holdings | C8: Consumer | D8: Private Equity | E8: Realized | F8: 43647 | G8: Crestline Partners | H8: United States | I8: Exit Process | J8: EBITDA multiple | K8: EBITDA multiple | L8: N | M8: Co-invest | N8: 1500000 | O8: 0.45 | P8: 0.35 | Q8: 0.2 | R8: 0 | S8: 0.05 | T8: No Nat Trust participation in the original deal. | U8: Fully exited consumer roll-up with strong realized gains. | V8: =SUMIFS(tblCashFlows[Contribution Amount],tblCashFlows[Investment ID],A8) | W8: =SUMIFS(tblCashFlows[Distribution Amount],tblCashFlows[Investment ID],A8) | X8: =XLOOKUP(A8,tblOfficialMarks[Investment ID],tblOfficialMarks[New Official Value],0,0,-1) | Y8: =XLOOKUP(A8,tblInternalModel[Investment ID],tblInternalModel[Final Internal Value],0,0,-1) | Z8: =XLOOKUP(A8,tblExitScenarios[Investment ID],tblExitScenarios[Net Exit Value],0,0,-1) | AA8: =IFERROR((W8+X8)/V8,"") | AB8: =IFERROR((W8+Y8)/V8,"") | AC8: =IFERROR((W8+Z8)/V8,"") | AD8: =IFERROR(LET(cf,FILTER(tblCashFlows[Net Cash Flow],tblCashFlows[Investment ID]=A8),dt,FILTER(tblCashFlows[Transaction Date],tblCashFlows[Investment ID]=A8),XIRR(VSTACK(cf,N(X8)),VSTACK(dt,TODAY()))),"") | AE8: =IFERROR(LET(cf,FILTER(tblCashFlows[Net Cash Flow],tblCashFlows[Investment ID]=A8),dt,FILTER(tblCashFlows[Transaction Date],tblCashFlows[Investment ID]=A8),XIRR(VSTACK(cf,N(Y8)),VSTACK(dt,TODAY()))),"") | AF8: =IFERROR(LET(cf,FILTER(tblCashFlows[Net Cash Flow],tblCashFlows[Investment ID]=A8),dt,FILTER(tblCashFlows[Transaction Date],tblCashFlows[Investment ID]=A8),XIRR(VSTACK(cf,N(Z8)),VSTACK(dt,TODAY()))),"")
A9: INV-006 | B9: Northshore BioTools | C9: Life Sciences | D9: Venture Equity | E9: Active | F9: 45233 | G9: Helix Ventures | H9: United States | I9: Cost | J9: Revenue multiple | K9: Revenue multiple | L9: N | M9: Co-invest | N9: 900000 | O9: 0 | P9: 0 | Q9: 0.55 | R9: 0.45 | S9: 0.09 | T9: Trust-only exposure. | U9: Diagnostics tools business with strong internal growth expectations. | V9: =SUMIFS(tblCashFlows[Contribution Amount],tblCashFlows[Investment ID],A9) | W9: =SUMIFS(tblCashFlows[Distribution Amount],tblCashFlows[Investment ID],A9) | X9: =XLOOKUP(A9,tblOfficialMarks[Investment ID],tblOfficialMarks[New Official Value],0,0,-1) | Y9: =XLOOKUP(A9,tblInternalModel[Investment ID],tblInternalModel[Final Internal Value],0,0,-1) | Z9: =XLOOKUP(A9,tblExitScenarios[Investment ID],tblExitScenarios[Net Exit Value],0,0,-1) | AA9: =IFERROR((W9+X9)/V9,"") | AB9: =IFERROR((W9+Y9)/V9,"") | AC9: =IFERROR((W9+Z9)/V9,"") | AD9: =IFERROR(LET(cf,FILTER(tblCashFlows[Net Cash Flow],tblCashFlows[Investment ID]=A9),dt,FILTER(tblCashFlows[Transaction Date],tblCashFlows[Investment ID]=A9),XIRR(VSTACK(cf,N(X9)),VSTACK(dt,TODAY()))),"") | AE9: =IFERROR(LET(cf,FILTER(tblCashFlows[Net Cash Flow],tblCashFlows[Investment ID]=A9),dt,FILTER(tblCashFlows[Transaction Date],tblCashFlows[Investment ID]=A9),XIRR(VSTACK(cf,N(Y9)),VSTACK(dt,TODAY()))),"") | AF9: =IFERROR(LET(cf,FILTER(tblCashFlows[Net Cash Flow],tblCashFlows[Investment ID]=A9),dt,FILTER(tblCashFlows[Transaction Date],tblCashFlows[Investment ID]=A9),XIRR(VSTACK(cf,N(Z9)),VSTACK(dt,TODAY()))),"")
A10: INV-007 | B10: Ironclad Energy Services | C10: Energy | D10: Private Equity | E10: Written Off | F10: 43202 | G10: Lone Star Capital | H10: United States | I10: Write-down | J10: Manual override | K10: Manual override | L10: N | M10: Co-invest | N10: 500000 | O10: 0.3 | P10: 0.2 | Q10: 0.25 | R10: 0.25 | S10: 0.03 | T10: Legacy position retained for historical performance tracking. | U10: Legacy oilfield services investment marked to zero. | V10: =SUMIFS(tblCashFlows[Contribution Amount],tblCashFlows[Investment ID],A10) | W10: =SUMIFS(tblCashFlows[Distribution Amount],tblCashFlows[Investment ID],A10) | X10: =XLOOKUP(A10,tblOfficialMarks[Investment ID],tblOfficialMarks[New Official Value],0,0,-1) | Y10: =XLOOKUP(A10,tblInternalModel[Investment ID],tblInternalModel[Final Internal Value],0,0,-1) | Z10: =XLOOKUP(A10,tblExitScenarios[Investment ID],tblExitScenarios[Net Exit Value],0,0,-1) | AA10: =IFERROR((W10+X10)/V10,"") | AB10: =IFERROR((W10+Y10)/V10,"") | AC10: =IFERROR((W10+Z10)/V10,"") | AD10: =IFERROR(LET(cf,FILTER(tblCashFlows[Net Cash Flow],tblCashFlows[Investment ID]=A10),dt,FILTER(tblCashFlows[Transaction Date],tblCashFlows[Investment ID]=A10),XIRR(VSTACK(cf,N(X10)),VSTACK(dt,TODAY()))),"") | AE10: =IFERROR(LET(cf,FILTER(tblCashFlows[Net Cash Flow],tblCashFlows[Investment ID]=A10),dt,FILTER(tblCashFlows[Transaction Date],tblCashFlows[Investment ID]=A10),XIRR(VSTACK(cf,N(Y10)),VSTACK(dt,TODAY()))),"") | AF10: =IFERROR(LET(cf,FILTER(tblCashFlows[Net Cash Flow],tblCashFlows[Investment ID]=A10),dt,FILTER(tblCashFlows[Transaction Date],tblCashFlows[Investment ID]=A10),XIRR(VSTACK(cf,N(Z10)),VSTACK(dt,TODAY()))),"")
A11: INV-008 | B11: Solstice Payments | C11: Fintech | D11: Growth Equity | E11: Active | F11: 45461 | G11: Meridian Growth | H11: Europe | I11: Priced Round | J11: Revenue multiple | K11: Revenue multiple | L11: N | M11: Lead | N11: 1750000 | O11: 0.35 | P11: 0.15 | Q11: 0.25 | R11: 0.25 | S11: 0.07 | T11: Recent core growth holding across all entities. | U11: Cross-border payments platform with scaling margins. | V11: =SUMIFS(tblCashFlows[Contribution Amount],tblCashFlows[Investment ID],A11) | W11: =SUMIFS(tblCashFlows[Distribution Amount],tblCashFlows[Investment ID],A11) | X11: =XLOOKUP(A11,tblOfficialMarks[Investment ID],tblOfficialMarks[New Official Value],0,0,-1) | Y11: =XLOOKUP(A11,tblInternalModel[Investment ID],tblInternalModel[Final Internal Value],0,0,-1) | Z11: =XLOOKUP(A11,tblExitScenarios[Investment ID],tblExitScenarios[Net Exit Value],0,0,-1) | AA11: =IFERROR((W11+X11)/V11,"") | AB11: =IFERROR((W11+Y11)/V11,"") | AC11: =IFERROR((W11+Z11)/V11,"") | AD11: =IFERROR(LET(cf,FILTER(tblCashFlows[Net Cash Flow],tblCashFlows[Investment ID]=A11),dt,FILTER(tblCashFlows[Transaction Date],tblCashFlows[Investment ID]=A11),XIRR(VSTACK(cf,N(X11)),VSTACK(dt,TODAY()))),"") | AE11: =IFERROR(LET(cf,FILTER(tblCashFlows[Net Cash Flow],tblCashFlows[Investment ID]=A11),dt,FILTER(tblCashFlows[Transaction Date],tblCashFlows[Investment ID]=A11),XIRR(VSTACK(cf,N(Y11)),VSTACK(dt,TODAY()))),"") | AF11: =IFERROR(LET(cf,FILTER(tblCashFlows[Net Cash Flow],tblCashFlows[Investment ID]=A11),dt,FILTER(tblCashFlows[Transaction Date],tblCashFlows[Investment ID]=A11),XIRR(VSTACK(cf,N(Z11)),VSTACK(dt,TODAY()))),"")

Sheet Cash Flow Ledger
A1: Capital Call & Distribution Ledger | Enter one dated cash flow per row
A2: Capital calls are negative in Net Cash Flow. Distributions are positive. This ledger feeds all XIRR calculations.
A3: Transaction ID | B3: Investment ID | C3: Investment Name | D3: Entity | E3: Transaction Date | F3: Transaction Type | G3: Description | H3: Contribution Amount | I3: Distribution Amount | J3: Net Cash Flow | K3: Realized / Unrealized flag | L3: Linked valuation date | M3: Notes
A4: TX-001 | B4: INV-001 | C4: Atlas Data Platforms | D4: Beaman Ventures | E4: 44635 | F4: Capital Call | G4: Initial close | H4: 400000 | I4: 0 | J4: =IF(H4="",0,-H4)+IF(I4="",0,I4)
A5: TX-002 | B5: INV-001 | C5: Atlas Data Platforms | D5: Lee Beaman | E5: 44635 | F5: Capital Call | G5: Initial close | H5: 300000 | I5: 0 | J5: =IF(H5="",0,-H5)+IF(I5="",0,I5)
A6: TX-003 | B6: INV-001 | C6: Atlas Data Platforms | D6: Kat Trust | E6: 44635 | F6: Capital Call | G6: Initial close | H6: 200000 | I6: 0 | J6: =IF(H6="",0,-H6)+IF(I6="",0,I6)
A7: TX-004 | B7: INV-001 | C7: Atlas Data Platforms | D7: Nat Trust | E7: 44635 | F7: Capital Call | G7: Initial close | H7: 100000 | I7: 0 | J7: =IF(H7="",0,-H7)+IF(I7="",0,I7)
A8: TX-005 | B8: INV-001 | C8: Atlas Data Platforms | D8: Beaman Ventures | E8: 45026 | F8: Capital Call | G8: Product expansion | H8: 120000 | I8: 0 | J8: =IF(H8="",0,-H8)+IF(I8="",0,I8)
A9: TX-006 | B9: INV-001 | C9: Atlas Data Platforms | D9: Lee Beaman | E9: 45026 | F9: Capital Call | G9: Product expansion | H9: 90000 | I9: 0 | J9: =IF(H9="",0,-H9)+IF(I9="",0,I9)
A10: TX-007 | B10: INV-001 | C10: Atlas Data Platforms | D10: Kat Trust | E10: 45026 | F10: Capital Call | G10: Product expansion | H10: 60000 | I10: 0 | J10: =IF(H10="",0,-H10)+IF(I10="",0,I10)
A11: TX-008 | B11: INV-001 | C11: Atlas Data Platforms | D11: Nat Trust | E11: 45026 | F11: Capital Call | G11: Product expansion | H11: 30000 | I11: 0 | J11: =IF(H11="",0,-H11)+IF(I11="",0,I11)
A12: TX-009 | B12: INV-002 | C12: Harbor Health Partners | D12: Beaman Ventures | E12: 44449 | F12: Capital Call | G12: Initial close | H12: 500000 | I12: 0 | J12: =IF(H12="",0,-H12)+IF(I12="",0,I12)
A13: TX-010 | B13: INV-002 | C13: Harbor Health Partners | D13: Kat Trust | E13: 44449 | F13: Capital Call | G13: Initial close | H13: 250000 | I13: 0 | J13: =IF(H13="",0,-H13)+IF(I13="",0,I13)
A14: TX-011 | B14: INV-002 | C14: Harbor Health Partners | D14: Nat Trust | E14: 44449 | F14: Capital Call | G14: Initial close | H14: 250000 | I14: 0 | J14: =IF(H14="",0,-H14)+IF(I14="",0,I14)
A15: TX-012 | B15: INV-002 | C15: Harbor Health Partners | D15: Beaman Ventures | E15: 44727 | F15: Capital Call | G15: Acquisition tuck-in | H15: 250000 | I15: 0 | J15: =IF(H15="",0,-H15)+IF(I15="",0,I15)
... A21: TX-018 | B21: INV-003 | C21: Summit Robotics | D21: Nat Trust | E21: 44237 | F21: Capital Call | G21: Bridge financing | H21: 80000 | I21: 0 | J21: =IF(H21="",0,-H21)+IF(I21="",0,I21)
A22: TX-019 | B22: INV-003 | C22: Summit Robotics | D22: Lee Beaman | E22: 45565 | F22: Partial Exit | G22: Secondary sale | H22: 0 | I22: 220000 | J22: =IF(H22="",0,-H22)+IF(I22="",0,I22) | K22: 45565
A23: TX-020 | B23: INV-003 | C23: Summit Robotics | D23: Nat Trust | E23: 45565 | F23: Partial Exit | G23: Secondary sale | H23: 0 | I23: 150000 | J23: =IF(H23="",0,-H23)+IF(I23="",0,I23) | K23: 45565
A24: TX-021 | B24: INV-003 | C24: Summit Robotics | D24: Lee Beaman | E24: 45703 | F24: Dividend | G24: Special dividend | H24: 0 | I24: 30000 | J24: =IF(H24="",0,-H24)+IF(I24="",0,I24)
A25: TX-022 | B25: INV-003 | C25: Summit Robotics | D25: Nat Trust | E25: 45703 | F25: Dividend | G25: Special dividend | H25: 0 | I25: 20000 | J25: =IF(H25="",0,-H25)+IF(I25="",0,I25)
A26: TX-023 | B26: INV-004 | C26: Cedar Credit Fund II | D26: Beaman Ventures | E26: 44581 | F26: Capital Call | G26: Fund drawdown | H26: 150000 | I26: 0 | J26: =IF(H26="",0,-H26)+IF(I26="",0,I26)
A27: TX-024 | B27: INV-004 | C27: Cedar Credit Fund II | D27: Lee Beaman | E27: 44581 | F27: Capital Call | G27: Fund drawdown | H27: 150000 | I27: 0 | J27: =IF(H27="",0,-H27)+IF(I27="",0,I27)
A28: TX-025 | B28: INV-004 | C28: Cedar Credit Fund II | D28: Kat Trust | E28: 44581 | F28: Capital Call | G28: Fund drawdown | H28: 150000 | I28: 0 | J28: =IF(H28="",0,-H28)+IF(I28="",0,I28)
A29: TX-026 | B29: INV-004 | C29: Cedar Credit Fund II | D29: Nat Trust | E29: 44581 | F29: Capital Call | G29: Fund drawdown | H29: 150000 | I29: 0 | J29: =IF(H29="",0,-H29)+IF(I29="",0,I29)
A30: TX-027 | B30: INV-004 | C30: Cedar Credit Fund II | D30: Beaman Ventures | E30: 44946 | F30: Capital Call | G30: Follow-on draw | H30: 100000 | I30: 0 | J30: =IF(H30="",0,-H30)+IF(I30="",0,I30)
A31: TX-028 | B31: INV-004 | C31: Cedar Credit Fund II | D31: Lee Beaman | E31: 44946 | F31: Capital Call | G31: Follow-on draw | H31: 100000 | I31: 0 | J31: =IF(H31="",0,-H31)+IF(I31="",0,I31)
A32: TX-029 | B32: INV-004 | C32: Cedar Credit Fund II | D32: Kat Trust | E32: 44946 | F32: Capital Call | G32: Follow-on draw | H32: 100000 | I32: 0 | J32: =IF(H32="",0,-H32)+IF(I32="",0,I32)
A33: TX-030 | B33: INV-004 | C33: Cedar Credit Fund II | D33: Nat Trust | E33: 44946 | F33: Capital Call | G33: Follow-on draw | H33: 100000 | I33: 0 | J33: =IF(H33="",0,-H33)+IF(I33="",0,I33)
A34: TX-031 | B34: INV-004 | C34: Cedar Credit Fund II | D34: Beaman Ventures | E34: 45641 | F34: Distribution | G34: Quarterly distribution | H34: 0 | I34: 40000 | J34: =IF(H34="",0,-H34)+IF(I34="",0,I34)
A35: TX-032 | B35: INV-004 | C35: Cedar Credit Fund II | D35: Lee Beaman | E35: 45641 | F35: Distribution | G35: Quarterly distribution | H35: 0 | I35: 40000 | J35: =IF(H35="",0,-H35)+IF(I35="",0,I35)
... A40: TX-037 | B40: INV-005 | C40: Meridian Consumer Holdings | D40: Kat Trust | E40: 43647 | F40: Capital Call | G40: Initial close | H40: 200000 | I40: 0 | J40: =IF(H40="",0,-H40)+IF(I40="",0,I40)
A41: TX-038 | B41: INV-005 | C41: Meridian Consumer Holdings | D41: Beaman Ventures | E41: 44561 | F41: Full Exit | G41: Sale to strategic buyer | H41: 0 | I41: 900000 | J41: =IF(H41="",0,-H41)+IF(I41="",0,I41) | K41: 44561
A42: TX-039 | B42: INV-005 | C42: Meridian Consumer Holdings | D42: Lee Beaman | E42: 44561 | F42: Full Exit | G42: Sale to strategic buyer | H42: 0 | I42: 700000 | J42: =IF(H42="",0,-H42)+IF(I42="",0,I42) | K42: 44561
A43: TX-040 | B43: INV-005 | C43: Meridian Consumer Holdings | D43: Kat Trust | E43: 44561 | F43: Full Exit | G43: Sale to strategic buyer | H43: 0 | I43: 400000 | J43: =IF(H43="",0,-H43)+IF(I43="",0,I43) | K43: 44561
A44: TX-041 | B44: INV-006 | C44: Northshore BioTools | D44: Kat Trust | E44: 45233 | F44: Capital Call | G44: Series B | H44: 330000 | I44: 0 | J44: =IF(H44="",0,-H44)+IF(I44="",0,I44)
A45: TX-042 | B45: INV-006 | C45: Northshore BioTools | D45: Nat Trust | E45: 45233 | F45: Capital Call | G45: Series B | H45: 270000 | I45: 0 | J45: =IF(H45="",0,-H45)+IF(I45="",0,I45)
A46: TX-043 | B46: INV-006 | C46: Northshore BioTools | D46: Kat Trust | E46: 45580 | F46: Capital Call | G46: Extension round | H46: 110000 | I46: 0 | J46: =IF(H46="",0,-H46)+IF(I46="",0,I46)
A47: TX-044 | B47: INV-006 | C47: Northshore BioTools | D47: Nat Trust | E47: 45580 | F47: Capital Call | G47: Extension round | H47: 90000 | I47: 0 | J47: =IF(H47="",0,-H47)+IF(I47="",0,I47)
A48: TX-045 | B48: INV-007 | C48: Ironclad Energy Services | D48: Beaman Ventures | E48: 43202 | F48: Capital Call | G48: Initial close | H48: 120000 | I48: 0 | J48: =IF(H48="",0,-H48)+IF(I48="",0,I48)
A49: TX-046 | B49: INV-007 | C49: Ironclad Energy Services | D49: Lee Beaman | E49: 43202 | F49: Capital Call | G49: Initial close | H49: 80000 | I49: 0 | J49: =IF(H49="",0,-H49)+IF(I49="",0,I49)
...

Sheet Official Valuation Ledger
A1: Official Valuation Ledger | Conservative reporting marks
A2: Default posture is cost until a priced round, transaction, or comparable external marker supports a new official mark.
A3: Valuation Date | B3: Investment ID | C3: Investment Name | D3: Entity or All-Entity View | E3: Prior Official Value | F3: New Official Value | G3: Change in Value | H3: Basis for Mark | I3: Mark Type | J3: Notes
A4: 45657 | B4: INV-001 | C4: Atlas Data Platforms | D4: All Entities | E4: 1000000 | F4: 1400000 | G4: =F4-E4 | H4: Priced Round
A5: 46022 | B5: INV-001 | C5: Atlas Data Platforms | D5: All Entities | E5: 1400000 | F5: 1600000 | G5: =F5-E5 | H5: Priced Round
A6: 46022 | B6: INV-002 | C6: Harbor Health Partners | D6: All Entities | E6: 1125000 | F6: 1125000 | G6: =F6-E6 | H6: Cost
A7: 46022 | B7: INV-003 | C7: Summit Robotics | D7: All Entities | E7: 350000 | F7: 420000 | G7: =F7-E7 | H7: Third-Party Transaction | I7: Partial liquidity achieved
A8: 46022 | B8: INV-004 | C8: Cedar Credit Fund II | D8: All Entities | E8: 1000000 | F8: 940000 | G8: =F8-E8 | H8: Other | I8: Conservative mark below internal NAV
A9: 44561 | B9: INV-005 | C9: Meridian Consumer Holdings | D9: All Entities | E9: 1000000 | F9: 0 | G9: =F9-E9 | H9: Exit Process
A10: 46022 | B10: INV-006 | C10: Northshore BioTools | D10: All Entities | E10: 800000 | F10: 800000 | G10: =F10-E10 | H10: Cost
A11: 46022 | B11: INV-007 | C11: Ironclad Energy Services | D11: All Entities | E11: 400000 | F11: 0 | G11: =F11-E11 | H11: Write-down | I11: Written to zero
A12: 46022 | B12: INV-008 | C12: Solstice Payments | D12: All Entities | E12: 1000000 | F12: 1250000 | G12: =F12-E12 | H12: Priced Round

Sheet Internal Valuation Model
A1: Internal Valuation Model | Team view of intrinsic value
A2: Use the selected method to drive value. Manual override takes precedence only when that method is selected.
A3: Investment ID | B3: Investment Name | C3: Valuation Date | D3: Valuation Method | E3: LTM Revenue | F3: LTM EBITDA | G3: EBITDA Multiple | H3: Revenue Multiple | I3: Enterprise Value | J3: Net Debt | K3: Equity Value | L3: Our Ownership % | M3: Our Value | N3: Discount / premium adjustment | O3: Manual override value | P3: Final Internal Value | Q3: Official Value | R3: Delta $ | S3: Delta % | T3: Notes
A4: INV-001 | B4: Atlas Data Platforms | C4: 46022 | D4: Revenue multiple | E4: 42000000 | F4: 0 | G4: 0 | H4: 6.2 | I4: =IF(D4="EBITDA multiple",F4*G4,IF(D4="Revenue multiple",E4*H4,IF(D4="NAV / asset-based",E4,IF(D4="Manual override",O4,0)))) | J4: 0 | K4: =IF(D4="NAV / asset-based",E4,I4-J4) | L4: 0 | M4: =K4*L4 | N4: 0 | P4: =IF(D4="Manual override",O4,M4*(1+N4)) | Q4: =XLOOKUP(A4,tblOfficialMarks[Investment ID],tblOfficialMarks[New Official Value],0,0,-1) | R4: =P4-Q4 | S4: =IFERROR(R4/Q4,"")
A5: INV-002 | B5: Harbor Health Partners | C5: 46022 | D5: EBITDA multiple | E5: 0 | F5: 18000000 | G5: 9.5 | H5: 0 | I5: =IF(D5="EBITDA multiple",F5*G5,IF(D5="Revenue multiple",E5*H5,IF(D5="NAV / asset-based",E5,IF(D5="Manual override",O5,0)))) | J5: 0 | K5: =IF(D5="NAV / asset-based",E5,I5-J5) | L5: 0 | M5: =K5*L5 | N5: 0 | P5: =IF(D5="Manual override",O5,M5*(1+N5)) | Q5: =XLOOKUP(A5,tblOfficialMarks[Investment ID],tblOfficialMarks[New Official Value],0,0,-1) | R5: =P5-Q5 | S5: =IFERROR(R5/Q5,"")
A6: INV-003 | B6: Summit Robotics | C6: 46022 | D6: Revenue multiple | E6: 21000000 | F6: 0 | G6: 0 | H6: 4.8 | I6: =IF(D6="EBITDA multiple",F6*G6,IF(D6="Revenue multiple",E6*H6,IF(D6="NAV / asset-based",E6,IF(D6="Manual override",O6,0)))) | J6: 0 | K6: =IF(D6="NAV / asset-based",E6,I6-J6) | L6: 0 | M6: =K6*L6 | N6: 0 | P6: =IF(D6="Manual override",O6,M6*(1+N6)) | Q6: =XLOOKUP(A6,tblOfficialMarks[Investment ID],tblOfficialMarks[New Official Value],0,0,-1) | R6: =P6-Q6 | S6: =IFERROR(R6/Q6,"")
A7: INV-004 | B7: Cedar Credit Fund II | C7: 46022 | D7: NAV / asset-based | E7: 0 | F7: 0 | G7: 0 | H7: 0 | I7: =IF(D7="EBITDA multiple",F7*G7,IF(D7="Revenue multiple",E7*H7,IF(D7="NAV / asset-based",E7,IF(D7="Manual override",O7,0)))) | J7: 0 | K7: =IF(D7="NAV / asset-based",E7,I7-J7) | L7: 0 | M7: =K7*L7 | N7: 0 | P7: =IF(D7="Manual override",O7,M7*(1+N7)) | Q7: =XLOOKUP(A7,tblOfficialMarks[Investment ID],tblOfficialMarks[New Official Value],0,0,-1) | R7: =P7-Q7 | S7: =IFERROR(R7/Q7,"")
A8: INV-005 | B8: Meridian Consumer Holdings | C8: 46022 | D8: EBITDA multiple | E8: 0 | F8: 0 | G8: 0 | H8: 0 | I8: =IF(D8="EBITDA multiple",F8*G8,IF(D8="Revenue multiple",E8*H8,IF(D8="NAV / asset-based",E8,IF(D8="Manual override",O8,0)))) | J8: 0 | K8: =IF(D8="NAV / asset-based",E8,I8-J8) | L8: 0 | M8: =K8*L8 | N8: 0 | O8: 0 | P8: =IF(D8="Manual override",O8,M8*(1+N8)) | Q8: =XLOOKUP(A8,tblOfficialMarks[Investment ID],tblOfficialMarks[New Official Value],0,0,-1) | R8: =P8-Q8 | S8: =IFERROR(R8/Q8,"")
A9: INV-006 | B9: Northshore BioTools | C9: 46022 | D9: Revenue multiple | E9: 24000000 | F9: 0 | G9: 0 | H9: 5 | I9: =IF(D9="EBITDA multiple",F9*G9,IF(D9="Revenue multiple",E9*H9,IF(D9="NAV / asset-based",E9,IF(D9="Manual override",O9,0)))) | J9: 0 | K9: =IF(D9="NAV / asset-based",E9,I9-J9) | L9: 0 | M9: =K9*L9 | N9: 0.05 | P9: =IF(D9="Manual override",O9,M9*(1+N9)) | Q9: =XLOOKUP(A9,tblOfficialMarks[Investment ID],tblOfficialMarks[New Official Value],0,0,-1) | R9: =P9-Q9 | S9: =IFERROR(R9/Q9,"")
A10: INV-007 | B10: Ironclad Energy Services | C10: 46022 | D10: Manual override | E10: 0 | F10: 0 | G10: 0 | H10: 0 | I10: =IF(D10="EBITDA multiple",F10*G10,IF(D10="Revenue multiple",E10*H10,IF(D10="NAV / asset-based",E10,IF(D10="Manual override",O10,0)))) | J10: 0 | K10: =IF(D10="NAV / asset-based",E10,I10-J10) | L10: 0 | M10: =K10*L10 | N10: 0 | O10: 0 | P10: =IF(D10="Manual override",O10,M10*(1+N10)) | Q10: =XLOOKUP(A10,tblOfficialMarks[Investment ID],tblOfficialMarks[New Official Value],0,0,-1) | R10: =P10-Q10 | S10: =IFERROR(R10/Q10,"")
A11: INV-008 | B11: Solstice Payments | C11: 46022 | D11: Revenue multiple | E11: 36000000 | F11: 0 | G11: 0 | H11: 5.8 | I11: =IF(D11="EBITDA multiple",F11*G11,IF(D11="Revenue multiple",E11*H11,IF(D11="NAV / asset-based",E11,IF(D11="Manual override",O11,0)))) | J11: 0 | K11: =IF(D11="NAV / asset-based",E11,I11-J11) | L11: 0 | M11: =K11*L11 | N11: 0 | P11: =IF(D11="Manual override",O11,M11*(1+N11)) | Q11: =XLOOKUP(A11,tblOfficialMarks[Investment ID],tblOfficialMarks[New Official Value],0,0,-1) | R11: =P11-Q11 | S11: =IFERROR(R11/Q11,"")

Sheet Exit Scenario Valuation
A1: Exit Scenario Valuation | Planning case only
A2: Exit values support scenario planning and should not be used as official NAV.
A3: Investment ID | B3: Investment Name | C3: Exit Date Assumption | D3: Exit Metric | E3: Exit Metric Amount | F3: Exit Multiple | G3: Enterprise Value | H3: Less Debt | I3: Equity Value | J3: Our Ownership % | K3: Gross Exit Value | L3: Estimated Fees / Taxes / Costs | M3: Net Exit Value | N3: Official Value | O3: Internal Value | P3: Upside vs Official | Q3: Upside vs Internal | R3: Notes
A4: INV-001 | B4: Atlas Data Platforms | C4: 46752 | D4: Revenue | E4: 50000000 | F4: 7 | G4: =IF(D4="Other",E4,E4*F4) | H4: 0.08 | I4: =G4-H4 | J4: Strategic sale scenario | K4: =I4*J4 | M4: =K4-L4 | N4: =XLOOKUP(A4,tblOfficialMarks[Investment ID],tblOfficialMarks[New Official Value],0,0,-1) | O4: =XLOOKUP(A4,tblInternalModel[Investment ID],tblInternalModel[Final Internal Value],0,0,-1) | P4: =M4-N4 | Q4: =M4-O4
A5: INV-002 | B5: Harbor Health Partners | C5: 46752 | D5: EBITDA | E5: 22000000 | F5: 11 | G5: =IF(D5="Other",E5,E5*F5) | H5: 0.12 | I5: =G5-H5 | J5: Sponsor sale after de-leveraging | K5: =I5*J5 | M5: =K5-L5 | N5: =XLOOKUP(A5,tblOfficialMarks[Investment ID],tblOfficialMarks[New Official Value],0,0,-1) | O5: =XLOOKUP(A5,tblInternalModel[Investment ID],tblInternalModel[Final Internal Value],0,0,-1) | P5: =M5-N5 | Q5: =M5-O5
A6: INV-003 | B6: Summit Robotics | C6: 46568 | D6: EBITDA | E6: 14000000 | F6: 12 | G6: =IF(D6="Other",E6,E6*F6) | H6: 0.065 | I6: =G6-H6 | J6: IPO / strategic sale case | K6: =I6*J6 | M6: =K6-L6 | N6: =XLOOKUP(A6,tblOfficialMarks[Investment ID],tblOfficialMarks[New Official Value],0,0,-1) | O6: =XLOOKUP(A6,tblInternalModel[Investment ID],tblInternalModel[Final Internal Value],0,0,-1) | P6: =M6-N6 | Q6: =M6-O6
A7: INV-004 | B7: Cedar Credit Fund II | C7: 46387 | D7: Other | E7: 980000 | F7: 1 | G7: =IF(D7="Other",E7,E7*F7) | H7: 0.04 | I7: =G7-H7 | J7: Wind-down at current NAV | K7: =I7*J7 | M7: =K7-L7 | N7: =XLOOKUP(A7,tblOfficialMarks[Investment ID],tblOfficialMarks[New Official Value],0,0,-1) | O7: =XLOOKUP(A7,tblInternalModel[Investment ID],tblInternalModel[Final Internal Value],0,0,-1) | P7: =M7-N7 | Q7: =M7-O7
A8: INV-005 | B8: Meridian Consumer Holdings | C8: 44561 | D8: EBITDA | E8: 0 | F8: 0 | G8: =IF(D8="Other",E8,E8*F8) | H8: 0.05 | I8: =G8-H8 | J8: Already exited | K8: =I8*J8 | M8: =K8-L8 | N8: =XLOOKUP(A8,tblOfficialMarks[Investment ID],tblOfficialMarks[New Official Value],0,0,-1) | O8: =XLOOKUP(A8,tblInternalModel[Investment ID],tblInternalModel[Final Internal Value],0,0,-1) | P8: =M8-N8 | Q8: =M8-O8
A9: INV-006 | B9: Northshore BioTools | C9: 47118 | D9: Revenue | E9: 32000000 | F9: 6 | G9: =IF(D9="Other",E9,E9*F9) | H9: 0.09 | I9: =G9-H9 | J9: Takeout by strategic diagnostics buyer | K9: =I9*J9 | M9: =K9-L9 | N9: =XLOOKUP(A9,tblOfficialMarks[Investment ID],tblOfficialMarks[New Official Value],0,0,-1) | O9: =XLOOKUP(A9,tblInternalModel[Investment ID],tblInternalModel[Final Internal Value],0,0,-1) | P9: =M9-N9 | Q9: =M9-O9
A10: INV-007 | B10: Ironclad Energy Services | C10: 46022 | D10: Other | E10: 0 | F10: 0 | G10: =IF(D10="Other",E10,E10*F10) | H10: 0.03 | I10: =G10-H10 | J10: No upside retained | K10: =I10*J10 | M10: =K10-L10 | N10: =XLOOKUP(A10,tblOfficialMarks[Investment ID],tblOfficialMarks[New Official Value],0,0,-1) | O10: =XLOOKUP(A10,tblInternalModel[Investment ID],tblInternalModel[Final Internal Value],0,0,-1) | P10: =M10-N10 | Q10: =M10-O10
A11: INV-008 | B11: Solstice Payments | C11: 47118 | D11: Revenue | E11: 46000000 | F11: 7 | G11: =IF(D11="Other",E11,E11*F11) | H11: 0.07 | I11: =G11-H11 | J11: M&A exit with modest transaction costs | K11: =I11*J11 | M11: =K11-L11 | N11: =XLOOKUP(A11,tblOfficialMarks[Investment ID],tblOfficialMarks[New Official Value],0,0,-1) | O11: =XLOOKUP(A11,tblInternalModel[Investment ID],tblInternalModel[Final Internal Value],0,0,-1) | P11: =M11-N11 | Q11: =M11-O11

Sheet Entity-Level Performance
A1: Entity-Level Performance | Snapshot
A3: Entity | B3: Total invested capital | C3: Total distributions | D3: Remaining cost basis | E3: Official NAV | F3: Internal NAV | G3: Exit Scenario NAV | H3: TVPI | I3: DPI | J3: RVPI | K3: Official XIRR | L3: Internal XIRR | M3: Exit Scenario XIRR | N3: Number of active investments | O3: Number of realized investments
A4: Beaman Ventures | B4: =SUMIFS(tblCashFlows[Contribution Amount],tblCashFlows[Entity],A4) | C4: =SUMIFS(tblCashFlows[Distribution Amount],tblCashFlows[Entity],A4) | D4: =MAX(0,B4-C4) | E4: =SUMPRODUCT(CHOOSE(MATCH(A4,EntityList,0),tblInvestments[Beaman Ventures %],tblInvestments[Lee Beaman %],tblInvestments[Kat Trust %],tblInvestments[Nat Trust %]),tblInvestments[Official current value]) | F4: =SUMPRODUCT(CHOOSE(MATCH(A4,EntityList,0),tblInvestments[Beaman Ventures %],tblInvestments[Lee Beaman %],tblInvestments[Kat Trust %],tblInvestments[Nat Trust %]),tblInvestments[Internal current value]) | G4: =SUMPRODUCT(CHOOSE(MATCH(A4,EntityList,0),tblInvestments[Beaman Ventures %],tblInvestments[Lee Beaman %],tblInvestments[Kat Trust %],tblInvestments[Nat Trust %]),tblInvestments[Exit scenario value]) | H4: =IFERROR((C4+E4)/B4,"") | I4: =IFERROR(C4/B4,"") | J4: =IFERROR(E4/B4,"") | K4: =IFERROR(LET(cf,FILTER(tblCashFlows[Net Cash Flow],tblCashFlows[Entity]=A4),dt,FILTER(tblCashFlows[Transaction Date],tblCashFlows[Entity]=A4),XIRR(VSTACK(cf,N(E4)),VSTACK(dt,TODAY()))),"") | L4: =IFERROR(LET(cf,FILTER(tblCashFlows[Net Cash Flow],tblCashFlows[Entity]=A4),dt,FILTER(tblCashFlows[Transaction Date],tblCashFlows[Entity]=A4),XIRR(VSTACK(cf,N(F4)),VSTACK(dt,TODAY()))),"") | M4: =IFERROR(LET(cf,FILTER(tblCashFlows[Net Cash Flow],tblCashFlows[Entity]=A4),dt,FILTER(tblCashFlows[Transaction Date],tblCashFlows[Entity]=A4),XIRR(VSTACK(cf,N(G4)),VSTACK(dt,TODAY()))),"") | N4: =SUMPRODUCT(--(CHOOSE(MATCH(A4,EntityList,0),tblInvestments[Beaman Ventures %],tblInvestments[Lee Beaman %],tblInvestments[Kat Trust %],tblInvestments[Nat Trust %])>0),--((tblInvestments[Status]="Active")+(tblInvestments[Status]="Partially Realized")>0)) | O4: =SUMPRODUCT(--(CHOOSE(MATCH(A4,EntityList,0),tblInvestments[Beaman Ventures %],tblInvestments[Lee Beaman %],tblInvestments[Kat Trust %],tblInvestments[Nat Trust %])>0),--(tblInvestments[Status]="Realized"))
A5: Lee Beaman | B5: =SUMIFS(tblCashFlows[Contribution Amount],tblCashFlows[Entity],A5) | C5: =SUMIFS(tblCashFlows[Distribution Amount],tblCashFlows[Entity],A5) | D5: =MAX(0,B5-C5) | E5: =SUMPRODUCT(CHOOSE(MATCH(A5,EntityList,0),tblInvestments[Beaman Ventures %],tblInvestments[Lee Beaman %],tblInvestments[Kat Trust %],tblInvestments[Nat Trust %]),tblInvestments[Official current value]) | F5: =SUMPRODUCT(CHOOSE(MATCH(A5,EntityList,0),tblInvestments[Beaman Ventures %],tblInvestments[Lee Beaman %],tblInvestments[Kat Trust %],tblInvestments[Nat Trust %]),tblInvestments[Internal current value]) | G5: =SUMPRODUCT(CHOOSE(MATCH(A5,EntityList,0),tblInvestments[Beaman Ventures %],tblInvestments[Lee Beaman %],tblInvestments[Kat Trust %],tblInvestments[Nat Trust %]),tblInvestments[Exit scenario value]) | H5: =IFERROR((C5+E5)/B5,"") | I5: =IFERROR(C5/B5,"") | J5: =IFERROR(E5/B5,"") | K5: =IFERROR(LET(cf,FILTER(tblCashFlows[Net Cash Flow],tblCashFlows[Entity]=A5),dt,FILTER(tblCashFlows[Transaction Date],tblCashFlows[Entity]=A5),XIRR(VSTACK(cf,N(E5)),VSTACK(dt,TODAY()))),"") | L5: =IFERROR(LET(cf,FILTER(tblCashFlows[Net Cash Flow],tblCashFlows[Entity]=A5),dt,FILTER(tblCashFlows[Transaction Date],tblCashFlows[Entity]=A5),XIRR(VSTACK(cf,N(F5)),VSTACK(dt,TODAY()))),"") | M5: =IFERROR(LET(cf,FILTER(tblCashFlows[Net Cash Flow],tblCashFlows[Entity]=A5),dt,FILTER(tblCashFlows[Transaction Date],tblCashFlows[Entity]=A5),XIRR(VSTACK(cf,N(G5)),VSTACK(dt,TODAY()))),"") | N5: =SUMPRODUCT(--(CHOOSE(MATCH(A5,EntityList,0),tblInvestments[Beaman Ventures %],tblInvestments[Lee Beaman %],tblInvestments[Kat Trust %],tblInvestments[Nat Trust %])>0),--((tblInvestments[Status]="Active")+(tblInvestments[Status]="Partially Realized")>0)) | O5: =SUMPRODUCT(--(CHOOSE(MATCH(A5,EntityList,0),tblInvestments[Beaman Ventures %],tblInvestments[Lee Beaman %],tblInvestments[Kat Trust %],tblInvestments[Nat Trust %])>0),--(tblInvestments[Status]="Realized"))
A6: Kat Trust | B6: =SUMIFS(tblCashFlows[Contribution Amount],tblCashFlows[Entity],A6) | C6: =SUMIFS(tblCashFlows[Distribution Amount],tblCashFlows[Entity],A6) | D6: =MAX(0,B6-C6) | E6: =SUMPRODUCT(CHOOSE(MATCH(A6,EntityList,0),tblInvestments[Beaman Ventures %],tblInvestments[Lee Beaman %],tblInvestments[Kat Trust %],tblInvestments[Nat Trust %]),tblInvestments[Official current value]) | F6: =SUMPRODUCT(CHOOSE(MATCH(A6,EntityList,0),tblInvestments[Beaman Ventures %],tblInvestments[Lee Beaman %],tblInvestments[Kat Trust %],tblInvestments[Nat Trust %]),tblInvestments[Internal current value]) | G6: =SUMPRODUCT(CHOOSE(MATCH(A6,EntityList,0),tblInvestments[Beaman Ventures %],tblInvestments[Lee Beaman %],tblInvestments[Kat Trust %],tblInvestments[Nat Trust %]),tblInvestments[Exit scenario value]) | H6: =IFERROR((C6+E6)/B6,"") | I6: =IFERROR(C6/B6,"") | J6: =IFERROR(E6/B6,"") | K6: =IFERROR(LET(cf,FILTER(tblCashFlows[Net Cash Flow],tblCashFlows[Entity]=A6),dt,FILTER(tblCashFlows[Transaction Date],tblCashFlows[Entity]=A6),XIRR(VSTACK(cf,N(E6)),VSTACK(dt,TODAY()))),"") | L6: =IFERROR(LET(cf,FILTER(tblCashFlows[Net Cash Flow],tblCashFlows[Entity]=A6),dt,FILTER(tblCashFlows[Transaction Date],tblCashFlows[Entity]=A6),XIRR(VSTACK(cf,N(F6)),VSTACK(dt,TODAY()))),"") | M6: =IFERROR(LET(cf,FILTER(tblCashFlows[Net Cash Flow],tblCashFlows[Entity]=A6),dt,FILTER(tblCashFlows[Transaction Date],tblCashFlows[Entity]=A6),XIRR(VSTACK(cf,N(G6)),VSTACK(dt,TODAY()))),"") | N6: =SUMPRODUCT(--(CHOOSE(MATCH(A6,EntityList,0),tblInvestments[Beaman Ventures %],tblInvestments[Lee Beaman %],tblInvestments[Kat Trust %],tblInvestments[Nat Trust %])>0),--((tblInvestments[Status]="Active")+(tblInvestments[Status]="Partially Realized")>0)) | O6: =SUMPRODUCT(--(CHOOSE(MATCH(A6,EntityList,0),tblInvestments[Beaman Ventures %],tblInvestments[Lee Beaman %],tblInvestments[Kat Trust %],tblInvestments[Nat Trust %])>0),--(tblInvestments[Status]="Realized"))
A7: Nat Trust | B7: =SUMIFS(tblCashFlows[Contribution Amount],tblCashFlows[Entity],A7) | C7: =SUMIFS(tblCashFlows[Distribution Amount],tblCashFlows[Entity],A7) | D7: =MAX(0,B7-C7) | E7: =SUMPRODUCT(CHOOSE(MATCH(A7,EntityList,0),tblInvestments[Beaman Ventures %],tblInvestments[Lee Beaman %],tblInvestments[Kat Trust %],tblInvestments[Nat Trust %]),tblInvestments[Official current value]) | F7: =SUMPRODUCT(CHOOSE(MATCH(A7,EntityList,0),tblInvestments[Beaman Ventures %],tblInvestments[Lee Beaman %],tblInvestments[Kat Trust %],tblInvestments[Nat Trust %]),tblInvestments[Internal current value]) | G7: =SUMPRODUCT(CHOOSE(MATCH(A7,EntityList,0),tblInvestments[Beaman Ventures %],tblInvestments[Lee Beaman %],tblInvestments[Kat Trust %],tblInvestments[Nat Trust %]),tblInvestments[Exit scenario value]) | H7: =IFERROR((C7+E7)/B7,"") | I7: =IFERROR(C7/B7,"") | J7: =IFERROR(E7/B7,"") | K7: =IFERROR(LET(cf,FILTER(tblCashFlows[Net Cash Flow],tblCashFlows[Entity]=A7),dt,FILTER(tblCashFlows[Transaction Date],tblCashFlows[Entity]=A7),XIRR(VSTACK(cf,N(E7)),VSTACK(dt,TODAY()))),"") | L7: =IFERROR(LET(cf,FILTER(tblCashFlows[Net Cash Flow],tblCashFlows[Entity]=A7),dt,FILTER(tblCashFlows[Transaction Date],tblCashFlows[Entity]=A7),XIRR(VSTACK(cf,N(F7)),VSTACK(dt,TODAY()))),"") | M7: =IFERROR(LET(cf,FILTER(tblCashFlows[Net Cash Flow],tblCashFlows[Entity]=A7),dt,FILTER(tblCashFlows[Transaction Date],tblCashFlows[Entity]=A7),XIRR(VSTACK(cf,N(G7)),VSTACK(dt,TODAY()))),"") | N7: =SUMPRODUCT(--(CHOOSE(MATCH(A7,EntityList,0),tblInvestments[Beaman Ventures %],tblInvestments[Lee Beaman %],tblInvestments[Kat Trust %],tblInvestments[Nat Trust %])>0),--((tblInvestments[Status]="Active")+(tblInvestments[Status]="Partially Realized")>0)) | O7: =SUMPRODUCT(--(CHOOSE(MATCH(A7,EntityList,0),tblInvestments[Beaman Ventures %],tblInvestments[Lee Beaman %],tblInvestments[Kat Trust %],tblInvestments[Nat Trust %])>0),--(tblInvestments[Status]="Realized"))
A10: Annualized view by calendar year
A11: Year | B11: Entity | C11: Contributions | D11: Distributions | E11: Net Cash Flow
A12: 2018 | B12: Beaman Ventures | C12: =SUMIFS(tblCashFlows[Contribution Amount],tblCashFlows[Entity],B12,tblCashFlows[Transaction Date],">="&DATE(A12,1,1),tblCashFlows[Transaction Date],"<"&DATE(A12+1,1,1)) | D12: =SUMIFS(tblCashFlows[Distribution Amount],tblCashFlows[Entity],B12,tblCashFlows[Transaction Date],">="&DATE(A12,1,1),tblCashFlows[Transaction Date],"<"&DATE(A12+1,1,1)) | E12: =D12-C12
A13: 2018 | B13: Lee Beaman | C13: =SUMIFS(tblCashFlows[Contribution Amount],tblCashFlows[Entity],B13,tblCashFlows[Transaction Date],">="&DATE(A13,1,1),tblCashFlows[Transaction Date],"<"&DATE(A13+1,1,1)) | D13: =SUMIFS(tblCashFlows[Distribution Amount],tblCashFlows[Entity],B13,tblCashFlows[Transaction Date],">="&DATE(A13,1,1),tblCashFlows[Transaction Date],"<"&DATE(A13+1,1,1)) | E13: =D13-C13
A14: 2018 | B14: Kat Trust | C14: =SUMIFS(tblCashFlows[Contribution Amount],tblCashFlows[Entity],B14,tblCashFlows[Transaction Date],">="&DATE(A14,1,1),tblCashFlows[Transaction Date],"<"&DATE(A14+1,1,1)) | D14: =SUMIFS(tblCashFlows[Distribution Amount],tblCashFlows[Entity],B14,tblCashFlows[Transaction Date],">="&DATE(A14,1,1),tblCashFlows[Transaction Date],"<"&DATE(A14+1,1,1)) | E14: =D14-C14
A15: 2018 | B15: Nat Trust | C15: =SUMIFS(tblCashFlows[Contribution Amount],tblCashFlows[Entity],B15,tblCashFlows[Transaction Date],">="&DATE(A15,1,1),tblCashFlows[Transaction Date],"<"&DATE(A15+1,1,1)) | D15: =SUMIFS(tblCashFlows[Distribution Amount],tblCashFlows[Entity],B15,tblCashFlows[Transaction Date],">="&DATE(A15,1,1),tblCashFlows[Transaction Date],"<"&DATE(A15+1,1,1)) | E15: =D15-C15
A16: 2019 | B16: Beaman Ventures | C16: =SUMIFS(tblCashFlows[Contribution Amount],tblCashFlows[Entity],B16,tblCashFlows[Transaction Date],">="&DATE(A16,1,1),tblCashFlows[Transaction Date],"<"&DATE(A16+1,1,1)) | D16: =SUMIFS(tblCashFlows[Distribution Amount],tblCashFlows[Entity],B16,tblCashFlows[Transaction Date],">="&DATE(A16,1,1),tblCashFlows[Transaction Date],"<"&DATE(A16+1,1,1)) | E16: =D16-C16
A17: 2019 | B17: Lee Beaman | C17: =SUMIFS(tblCashFlows[Contribution Amount],tblCashFlows[Entity],B17,tblCashFlows[Transaction Date],">="&DATE(A17,1,1),tblCashFlows[Transaction Date],"<"&DATE(A17+1,1,1)) | D17: =SUMIFS(tblCashFlows[Distribution Amount],tblCashFlows[Entity],B17,tblCashFlows[Transaction Date],">="&DATE(A17,1,1),tblCashFlows[Transaction Date],"<"&DATE(A17+1,1,1)) | E17: =D17-C17
A18: 2019 | B18: Kat Trust | C18: =SUMIFS(tblCashFlows[Contribution Amount],tblCashFlows[Entity],B18,tblCashFlows[Transaction Date],">="&DATE(A18,1,1),tblCashFlows[Transaction Date],"<"&DATE(A18+1,1,1)) | D18: =SUMIFS(tblCashFlows[Distribution Amount],tblCashFlows[Entity],B18,tblCashFlows[Transaction Date],">="&DATE(A18,1,1),tblCashFlows[Transaction Date],"<"&DATE(A18+1,1,1)) | E18: =D18-C18
A19: 2019 | B19: Nat Trust | C19: =SUMIFS(tblCashFlows[Contribution Amount],tblCashFlows[Entity],B19,tblCashFlows[Transaction Date],">="&DATE(A19,1,1),tblCashFlows[Transaction Date],"<"&DATE(A19+1,1,1)) | D19: =SUMIFS(tblCashFlows[Distribution Amount],tblCashFlows[Entity],B19,tblCashFlows[Transaction Date],">="&DATE(A19,1,1),tblCashFlows[Transaction Date],"<"&DATE(A19+1,1,1)) | E19: =D19-C19
A20: 2020 | B20: Beaman Ventures | C20: =SUMIFS(tblCashFlows[Contribution Amount],tblCashFlows[Entity],B20,tblCashFlows[Transaction Date],">="&DATE(A20,1,1),tblCashFlows[Transaction Date],"<"&DATE(A20+1,1,1)) | D20: =SUMIFS(tblCashFlows[Distribution Amount],tblCashFlows[Entity],B20,tblCashFlows[Transaction Date],">="&DATE(A20,1,1),tblCashFlows[Transaction Date],"<"&DATE(A20+1,1,1)) | E20: =D20-C20
A21: 2020 | B21: Lee Beaman | C21: =SUMIFS(tblCashFlows[Contribution Amount],tblCashFlows[Entity],B21,tblCashFlows[Transaction Date],">="&DATE(A21,1,1),tblCashFlows[Transaction Date],"<"&DATE(A21+1,1,1)) | D21: =SUMIFS(tblCashFlows[Distribution Amount],tblCashFlows[Entity],B21,tblCashFlows[Transaction Date],">="&DATE(A21,1,1),tblCashFlows[Transaction Date],"<"&DATE(A21+1,1,1)) | E21: =D21-C21
A22: 2020 | B22: Kat Trust | C22: =SUMIFS(tblCashFlows[Contribution Amount],tblCashFlows[Entity],B22,tblCashFlows[Transaction Date],">="&DATE(A22,1,1),tblCashFlows[Transaction Date],"<"&DATE(A22+1,1,1)) | D22: =SUMIFS(tblCashFlows[Distribution Amount],tblCashFlows[Entity],B22,tblCashFlows[Transaction Date],">="&DATE(A22,1,1),tblCashFlows[Transaction Date],"<"&DATE(A22+1,1,1)) | E22: =D22-C22
A23: 2020 | B23: Nat Trust | C23: =SUMIFS(tblCashFlows[Contribution Amount],tblCashFlows[Entity],B23,tblCashFlows[Transaction Date],">="&DATE(A23,1,1),tblCashFlows[Transaction Date],"<"&DATE(A23+1,1,1)) | D23: =SUMIFS(tblCashFlows[Distribution Amount],tblCashFlows[Entity],B23,tblCashFlows[Transaction Date],">="&DATE(A23,1,1),tblCashFlows[Transaction Date],"<"&DATE(A23+1,1,1)) | E23: =D23-C23
... A47: 2026 | B47: Nat Trust | C47: =SUMIFS(tblCashFlows[Contribution Amount],tblCashFlows[Entity],B47,tblCashFlows[Transaction Date],">="&DATE(A47,1,1),tblCashFlows[Transaction Date],"<"&DATE(A47+1,1,1)) | D47: =SUMIFS(tblCashFlows[Distribution Amount],tblCashFlows[Entity],B47,tblCashFlows[Transaction Date],">="&DATE(A47,1,1),tblCashFlows[Transaction Date],"<"&DATE(A47+1,1,1)) | E47: =D47-C47

Sheet Investment-Level Performance
A1: Investment-Level Performance | One row per investment
A3: Investment ID | B3: Investment Name | C3: Status | D3: Total Invested Capital | E3: Total Distributions | F3: Official Value | G3: Internal Value | H3: Exit Value | I3: Official TVPI | J3: Internal TVPI | K3: Exit TVPI | L3: Official XIRR | M3: Internal XIRR | N3: Exit XIRR | O3: Unrealized Gain / Loss | P3: Realized Gain / Loss | Q3: Total Gain / Loss | R3: Holding Period | S3: Which entities own it | T3: Stale mark?
A4: INV-001 | B4: =XLOOKUP(A4,tblInvestments[Investment ID],tblInvestments[Investment Name],"") | C4: =XLOOKUP(A4,tblInvestments[Investment ID],tblInvestments[Status],"") | D4: =XLOOKUP(A4,tblInvestments[Investment ID],tblInvestments[Total invested capital],0) | E4: =XLOOKUP(A4,tblInvestments[Investment ID],tblInvestments[Total distributions],0) | F4: =XLOOKUP(A4,tblInvestments[Investment ID],tblInvestments[Official current value],0) | G4: =XLOOKUP(A4,tblInvestments[Investment ID],tblInvestments[Internal current value],0) | H4: =XLOOKUP(A4,tblInvestments[Investment ID],tblInvestments[Exit scenario value],0) | I4: =IFERROR((E4+F4)/D4,"") | J4: =IFERROR((E4+G4)/D4,"") | K4: =IFERROR((E4+H4)/D4,"") | L4: =XLOOKUP(A4,tblInvestments[Investment ID],tblInvestments[Official XIRR],"") | M4: =XLOOKUP(A4,tblInvestments[Investment ID],tblInvestments[Internal XIRR],"") | N4: =XLOOKUP(A4,tblInvestments[Investment ID],tblInvestments[Exit XIRR],"") | O4: =F4-MAX(0,D4-E4) | P4: =MAX(0,E4-D4) | Q4: =E4+F4-D4 | R4: =YEARFRAC(XLOOKUP(A4,tblInvestments[Investment ID],tblInvestments[Initial Investment Date],TODAY()),TODAY()) | S4: =TEXTJOIN(", ",TRUE,IF(XLOOKUP(A4,tblInvestments[Investment ID],tblInvestments[Beaman Ventures %],0)>0,"Beaman Ventures",""),IF(XLOOKUP(A4,tblInvestments[Investment ID],tblInvestments[Lee Beaman %],0)>0,"Lee Beaman",""),IF(XLOOKUP(A4,tblInvestments[Investment ID],tblInvestments[Kat Trust %],0)>0,"Kat Trust",""),IF(XLOOKUP(A4,tblInvestments[Investment ID],tblInvestments[Nat Trust %],0)>0,"Nat Trust","")) | T4: =IF(TODAY()-XLOOKUP(A4,tblOfficialMarks[Investment ID],tblOfficialMarks[Valuation Date],TODAY(),0,-1)>120,"Update mark","Current")
A5: INV-002 | B5: =XLOOKUP(A5,tblInvestments[Investment ID],tblInvestments[Investment Name],"") | C5: =XLOOKUP(A5,tblInvestments[Investment ID],tblInvestments[Status],"") | D5: =XLOOKUP(A5,tblInvestments[Investment ID],tblInvestments[Total invested capital],0) | E5: =XLOOKUP(A5,tblInvestments[Investment ID],tblInvestments[Total distributions],0) | F5: =XLOOKUP(A5,tblInvestments[Investment ID],tblInvestments[Official current value],0) | G5: =XLOOKUP(A5,tblInvestments[Investment ID],tblInvestments[Internal current value],0) | H5: =XLOOKUP(A5,tblInvestments[Investment ID],tblInvestments[Exit scenario value],0) | I5: =IFERROR((E5+F5)/D5,"") | J5: =IFERROR((E5+G5)/D5,"") | K5: =IFERROR((E5+H5)/D5,"") | L5: =XLOOKUP(A5,tblInvestments[Investment ID],tblInvestments[Official XIRR],"") | M5: =XLOOKUP(A5,tblInvestments[Investment ID],tblInvestments[Internal XIRR],"") | N5: =XLOOKUP(A5,tblInvestments[Investment ID],tblInvestments[Exit XIRR],"") | O5: =F5-MAX(0,D5-E5) | P5: =MAX(0,E5-D5) | Q5: =E5+F5-D5 | R5: =YEARFRAC(XLOOKUP(A5,tblInvestments[Investment ID],tblInvestments[Initial Investment Date],TODAY()),TODAY()) | S5: =TEXTJOIN(", ",TRUE,IF(XLOOKUP(A5,tblInvestments[Investment ID],tblInvestments[Beaman Ventures %],0)>0,"Beaman Ventures",""),IF(XLOOKUP(A5,tblInvestments[Investment ID],tblInvestments[Lee Beaman %],0)>0,"Lee Beaman",""),IF(XLOOKUP(A5,tblInvestments[Investment ID],tblInvestments[Kat Trust %],0)>0,"Kat Trust",""),IF(XLOOKUP(A5,tblInvestments[Investment ID],tblInvestments[Nat Trust %],0)>0,"Nat Trust","")) | T5: =IF(TODAY()-XLOOKUP(A5,tblOfficialMarks[Investment ID],tblOfficialMarks[Valuation Date],TODAY(),0,-1)>120,"Update mark","Current")
